LOCAL_RANK: 0 - CUDA_VISIBLE_DEVICES: [0]

  | Name                   | Type                         | Params | Mode
--------------------------------------------------------------------------------
0 | sparse_encoder         | SparseContextEncoder         | 231 K  | train
1 | mamba_layer            | MambaLayer                   | 330 K  | train
2 | high_level_model       | HighLevelInteractionModel    | 1.2 M  | train
3 | lane_probability_model | LaneAwareProbabilityLearning | 347 K  | train
4 | laplace_decoder        | MultimodalLaplaceDecoder     | 516    | train
--------------------------------------------------------------------------------
2.1 M     Trainable params
0         Non-trainable params
2.1 M     Total params
8.515     Total estimated model params size (MB)
90        Modules in train mode
0         Modules in eval mode
Sanity Checking: |                                                                                                                                                                        | 0/? [00:00<?, ?it/s]
Error executing job with overrides: ['+task=train']
Traceback (most recent call last):
  File "/home/user/Traj-LLM/imjaegyun/Traj-LLM/train.py", line 26, in <module>
    main()
  File "/home/user/anaconda3/envs/im_jg/lib/python3.9/site-packages/hydra/main.py", line 94, in decorated_main
    _run_hydra(
  File "/home/user/anaconda3/envs/im_jg/lib/python3.9/site-packages/hydra/_internal/utils.py", line 394, in _run_hydra
    _run_app(
  File "/home/user/anaconda3/envs/im_jg/lib/python3.9/site-packages/hydra/_internal/utils.py", line 457, in _run_app
    run_and_report(
  File "/home/user/anaconda3/envs/im_jg/lib/python3.9/site-packages/hydra/_internal/utils.py", line 223, in run_and_report
    raise ex
  File "/home/user/anaconda3/envs/im_jg/lib/python3.9/site-packages/hydra/_internal/utils.py", line 220, in run_and_report
    return func()
  File "/home/user/anaconda3/envs/im_jg/lib/python3.9/site-packages/hydra/_internal/utils.py", line 458, in <lambda>
    lambda: hydra.run(
  File "/home/user/anaconda3/envs/im_jg/lib/python3.9/site-packages/hydra/_internal/hydra.py", line 132, in run
    _ = ret.return_value
  File "/home/user/anaconda3/envs/im_jg/lib/python3.9/site-packages/hydra/core/utils.py", line 260, in return_value
    raise self._return_value
  File "/home/user/anaconda3/envs/im_jg/lib/python3.9/site-packages/hydra/core/utils.py", line 186, in run_job
    ret.return_value = task_function(task_cfg)
  File "/home/user/Traj-LLM/imjaegyun/Traj-LLM/train.py", line 15, in main
    train_main(config)  # train_main에 DictConfig 전달
  File "/home/user/Traj-LLM/imjaegyun/Traj-LLM/train/train_model.py", line 192, in train_main
    trainer.fit(model, train_loader, val_loader)
  File "/home/user/anaconda3/envs/im_jg/lib/python3.9/site-packages/pytorch_lightning/trainer/trainer.py", line 539, in fit
    call._call_and_handle_interrupt(
  File "/home/user/anaconda3/envs/im_jg/lib/python3.9/site-packages/pytorch_lightning/trainer/call.py", line 47, in _call_and_handle_interrupt
    return trainer_fn(*args, **kwargs)
  File "/home/user/anaconda3/envs/im_jg/lib/python3.9/site-packages/pytorch_lightning/trainer/trainer.py", line 575, in _fit_impl
    self._run(model, ckpt_path=ckpt_path)
  File "/home/user/anaconda3/envs/im_jg/lib/python3.9/site-packages/pytorch_lightning/trainer/trainer.py", line 982, in _run
    results = self._run_stage()
  File "/home/user/anaconda3/envs/im_jg/lib/python3.9/site-packages/pytorch_lightning/trainer/trainer.py", line 1024, in _run_stage
    self._run_sanity_check()
  File "/home/user/anaconda3/envs/im_jg/lib/python3.9/site-packages/pytorch_lightning/trainer/trainer.py", line 1053, in _run_sanity_check
    val_loop.run()
  File "/home/user/anaconda3/envs/im_jg/lib/python3.9/site-packages/pytorch_lightning/loops/utilities.py", line 179, in _decorator
    return loop_run(self, *args, **kwargs)
  File "/home/user/anaconda3/envs/im_jg/lib/python3.9/site-packages/pytorch_lightning/loops/evaluation_loop.py", line 137, in run
    batch, batch_idx, dataloader_idx = next(data_fetcher)
  File "/home/user/anaconda3/envs/im_jg/lib/python3.9/site-packages/pytorch_lightning/loops/fetchers.py", line 134, in __next__
    batch = super().__next__()
  File "/home/user/anaconda3/envs/im_jg/lib/python3.9/site-packages/pytorch_lightning/loops/fetchers.py", line 61, in __next__
    batch = next(self.iterator)
  File "/home/user/anaconda3/envs/im_jg/lib/python3.9/site-packages/pytorch_lightning/utilities/combined_loader.py", line 341, in __next__
    out = next(self._iterator)
  File "/home/user/anaconda3/envs/im_jg/lib/python3.9/site-packages/pytorch_lightning/utilities/combined_loader.py", line 142, in __next__
    out = next(self.iterators[0])
  File "/home/user/anaconda3/envs/im_jg/lib/python3.9/site-packages/torch/utils/data/dataloader.py", line 630, in __next__
    data = self._next_data()
  File "/home/user/anaconda3/envs/im_jg/lib/python3.9/site-packages/torch/utils/data/dataloader.py", line 1345, in _next_data
    return self._process_data(data)
  File "/home/user/anaconda3/envs/im_jg/lib/python3.9/site-packages/torch/utils/data/dataloader.py", line 1371, in _process_data
    data.reraise()
  File "/home/user/anaconda3/envs/im_jg/lib/python3.9/site-packages/torch/_utils.py", line 694, in reraise
    raise exception
KeyError: Caught KeyError in DataLoader worker process 0.
Original Traceback (most recent call last):
  File "/home/user/anaconda3/envs/im_jg/lib/python3.9/site-packages/torch/utils/data/_utils/worker.py", line 308, in _worker_loop
    data = fetcher.fetch(index)
  File "/home/user/anaconda3/envs/im_jg/lib/python3.9/site-packages/torch/utils/data/_utils/fetch.py", line 51, in fetch
    data = [self.dataset[idx] for idx in possibly_batched_index]
  File "/home/user/anaconda3/envs/im_jg/lib/python3.9/site-packages/torch/utils/data/_utils/fetch.py", line 51, in <listcomp>
    data = [self.dataset[idx] for idx in possibly_batched_index]
  File "/home/user/Traj-LLM/imjaegyun/Traj-LLM/data/nuscenes_data_loader.py", line 115, in __getitem__
    instance_token = sample['instance_token']
KeyError: 'instance_token'
